Workbook

Sheet Resumen
A1: CASHFLOW — Proyecto ILS/DME Turquía (DHMİ)
A2: TR_GE654D_21 · Licitación 2026/760533 · 21 sistemas ILS/DME + 1 LLZ/DME
A3: Modelo de estimación — cifras a confirmar con la oferta económica real (aún no existe modelo de Turquía)
A5: Valor de contrato (sin IVA) | B5: =Parámetros!B2
A6: Ingresos totales | B6: =SUM(Cashflow!F4:F69)
A7: Costes totales | B7: =SUM(Cashflow!I4:I69)+SUM(Cashflow!J4:J69)+SUM(Cashflow!K4:K69)
A8: Margen bruto € | B8: =B6-B7
A9: Margen bruto % | B9: =B8/B6
A10: PICO de necesidad de financiación (caja mín.) | B10: =MIN(Cashflow!M4:M69)
A11: Caja final acumulada | B11: =Cashflow!M69
A12: Coste financiero del gap (estimado) | B12: =SUM(Cashflow!L4:L69)
A13: Avales inmovilizados (provisional + cumplimiento) | B13: =Parámetros!B11+Parámetros!B10
A16: Estructura de cobro (por contrato, Art. 12.2.3 / 7.2):
A17: 40% contra embarque · 50% tras formación + PAC · 10% tras FAC · SIN anticipo (Art. 13.1)
A18: Entrega en máx. 3 embarques en máx. 840 días · FAC 12 meses tras PAC · garantía 2 años tras FAC · sin revisión de precios (Art. 14)

Sheet Parámetros
A1: PARÁMETROS (editables)
A2: Valor de contrato sin IVA (EUR) | B2: 20000000
A3: Fecha commencement (firma EKAP) | B3: 46388
A4: Duración (meses) | B4: 66
A5: % equipos (Indra/IACIT) | B5: 0.65
A6: % instalación+logística+aduanas | B6: 0.15
A7: Margen bruto objetivo | B7: 0.2
A8: Anticipo a proveedor al pedido | B8: 0.3
A9: Pago a proveedor al embarque | B9: 0.7
A10: Lead de pedido antes de embarque (meses) | B10: 6
A11: Aval de cumplimiento 6% (EUR) | B11: 1200000
A12: Aval provisional/bid bond 3% (EUR) | B12: 600000
A13: Coste anual de avales | B13: 0.015
A14: Coste financiero anual sobre saldo negativo | B14: 0.06
A17: Nota: las cifras de coste y el valor de contrato son ESTIMACIONES.
A18: No existe todavía una oferta económica de Turquía (la carpeta 01_Economical_Proposals solo tiene plantillas de otros países).

Sheet Cashflow
A1: CASHFLOW MENSUAL (estimado)
A3: Mes # | B3: Fecha | C3: Fase / Hito | D3: Cobro 40% embarque | E3: Cobro 50% PAC | F3: Cobro 10% FAC | G3: INGRESOS mes | H3: Pago equipos (Indra) | I3: Pago instalación | J3: Coste avales | K3: Coste financiero | L3: COSTES mes | M3: NETO mes | N3: CAJA acumulada
A4: 1 | B4: 46388 | C4: Firma contrato (commencement) | D4: 0 | E4: 0 | F4: 0 | G4: =SUM(D4:F4) | H4: 0 | I4: 0 | J4: =Parámetros!$B$10*Parámetros!$B$12/12 | K4: =IF(0<0,-0*Parámetros!$B$13/12,0) | L4: =SUM(H4:K4) | M4: =G4-L4 | N4: =M4
A5: 2 | B5: 46419 | D5: 0 | E5: 0 | F5: 0 | G5: =SUM(D5:F5) | H5: 1300000 | I5: 0 | J5: =Parámetros!$B$10*Parámetros!$B$12/12 | K5: =IF(N4<0,-N4*Parámetros!$B$13/12,0) | L5: =SUM(H5:K5) | M5: =G5-L5 | N5: =N4+M5
A6: 3 | B6: 46447 | D6: 0 | E6: 0 | F6: 0 | G6: =SUM(D6:F6) | H6: 0 | I6: 0 | J6: =Parámetros!$B$10*Parámetros!$B$12/12 | K6: =IF(N5<0,-N5*Parámetros!$B$13/12,0) | L6: =SUM(H6:K6) | M6: =G6-L6 | N6: =N5+M6
A7: 4 | B7: 46478 | D7: 0 | E7: 0 | F7: 0 | G7: =SUM(D7:F7) | H7: 0 | I7: 0 | J7: =Parámetros!$B$10*Parámetros!$B$12/12 | K7: =IF(N6<0,-N6*Parámetros!$B$13/12,0) | L7: =SUM(H7:K7) | M7: =G7-L7 | N7: =N6+M7
A8: 5 | B8: 46508 | D8: 0 | E8: 0 | F8: 0 | G8: =SUM(D8:F8) | H8: 0 | I8: 0 | J8: =Parámetros!$B$10*Parámetros!$B$12/12 | K8: =IF(N7<0,-N7*Parámetros!$B$13/12,0) | L8: =SUM(H8:K8) | M8: =G8-L8 | N8: =N7+M8
A9: 6 | B9: 46539 | D9: 0 | E9: 0 | F9: 0 | G9: =SUM(D9:F9) | H9: 0 | I9: 0 | J9: =Parámetros!$B$10*Parámetros!$B$12/12 | K9: =IF(N8<0,-N8*Parámetros!$B$13/12,0) | L9: =SUM(H9:K9) | M9: =G9-L9 | N9: =N8+M9
A10: 7 | B10: 46569 | D10: 0 | E10: 0 | F10: 0 | G10: =SUM(D10:F10) | H10: 0 | I10: 0 | J10: =Parámetros!$B$10*Parámetros!$B$12/12 | K10: =IF(N9<0,-N9*Parámetros!$B$13/12,0) | L10: =SUM(H10:K10) | M10: =G10-L10 | N10: =N9+M10
A11: 8 | B11: 46600 | C11: Embarque lote 1 | D11: 2666667 | E11: 0 | F11: 0 | G11: =SUM(D11:F11) | H11: 3033333 | I11: 166667 | J11: =Parámetros!$B$10*Parámetros!$B$12/12 | K11: =IF(N10<0,-N10*Parámetros!$B$13/12,0) | L11: =SUM(H11:K11) | M11: =G11-L11 | N11: =N10+M11
A12: 9 | B12: 46631 | D12: 0 | E12: 0 | F12: 0 | G12: =SUM(D12:F12) | H12: 0 | I12: 166667 | J12: =Parámetros!$B$10*Parámetros!$B$12/12 | K12: =IF(N11<0,-N11*Parámetros!$B$13/12,0) | L12: =SUM(H12:K12) | M12: =G12-L12 | N12: =N11+M12
A13: 10 | B13: 46661 | D13: 0 | E13: 0 | F13: 0 | G13: =SUM(D13:F13) | H13: 1300000 | I13: 166667 | J13: =Parámetros!$B$10*Parámetros!$B$12/12 | K13: =IF(N12<0,-N12*Parámetros!$B$13/12,0) | L13: =SUM(H13:K13) | M13: =G13-L13 | N13: =N12+M13
A14: 11 | B14: 46692 | D14: 0 | E14: 0 | F14: 0 | G14: =SUM(D14:F14) | H14: 0 | I14: 166667 | J14: =Parámetros!$B$10*Parámetros!$B$12/12 | K14: =IF(N13<0,-N13*Parámetros!$B$13/12,0) | L14: =SUM(H14:K14) | M14: =G14-L14 | N14: =N13+M14
A15: 12 | B15: 46722 | D15: 0 | E15: 0 | F15: 0 | G15: =SUM(D15:F15) | H15: 0 | I15: 166667 | J15: =Parámetros!$B$10*Parámetros!$B$12/12 | K15: =IF(N14<0,-N14*Parámetros!$B$13/12,0) | L15: =SUM(H15:K15) | M15: =G15-L15 | N15: =N14+M15
A16: 13 | B16: 46753 | D16: 0 | E16: 0 | F16: 0 | G16: =SUM(D16:F16) | H16: 0 | I16: 166667 | J16: =Parámetros!$B$10*Parámetros!$B$12/12 | K16: =IF(N15<0,-N15*Parámetros!$B$13/12,0) | L16: =SUM(H16:K16) | M16: =G16-L16 | N16: =N15+M16
A17: 14 | B17: 46784 | C17: PAC lote 1 | D17: 0 | E17: 3333333 | F17: 0 | G17: =SUM(D17:F17) | H17: 0 | I17: 0 | J17: =Parámetros!$B$10*Parámetros!$B$12/12 | K17: =IF(N16<0,-N16*Parámetros!$B$13/12,0) | L17: =SUM(H17:K17) | M17: =G17-L17 | N17: =N16+M17
A18: 15 | B18: 46813 | D18: 0 | E18: 0 | F18: 0 | G18: =SUM(D18:F18) | H18: 0 | I18: 0 | J18: =Parámetros!$B$10*Parámetros!$B$12/12 | K18: =IF(N17<0,-N17*Parámetros!$B$13/12,0) | L18: =SUM(H18:K18) | M18: =G18-L18 | N18: =N17+M18
A19: 16 | B19: 46844 | C19: Embarque lote 2 | D19: 2666667 | E19: 0 | F19: 0 | G19: =SUM(D19:F19) | H19: 3033333 | I19: 166667 | J19: =Parámetros!$B$10*Parámetros!$B$12/12 | K19: =IF(N18<0,-N18*Parámetros!$B$13/12,0) | L19: =SUM(H19:K19) | M19: =G19-L19 | N19: =N18+M19
A20: 17 | B20: 46874 | D20: 0 | E20: 0 | F20: 0 | G20: =SUM(D20:F20) | H20: 0 | I20: 166667 | J20: =Parámetros!$B$10*Parámetros!$B$12/12 | K20: =IF(N19<0,-N19*Parámetros!$B$13/12,0) | L20: =SUM(H20:K20) | M20: =G20-L20 | N20: =N19+M20
A21: 18 | B21: 46905 | D21: 0 | E21: 0 | F21: 0 | G21: =SUM(D21:F21) | H21: 1300000 | I21: 166667 | J21: =Parámetros!$B$10*Parámetros!$B$12/12 | K21: =IF(N20<0,-N20*Parámetros!$B$13/12,0) | L21: =SUM(H21:K21) | M21: =G21-L21 | N21: =N20+M21
A22: 19 | B22: 46935 | D22: 0 | E22: 0 | F22: 0 | G22: =SUM(D22:F22) | H22: 0 | I22: 166667 | J22: =Parámetros!$B$10*Parámetros!$B$12/12 | K22: =IF(N21<0,-N21*Parámetros!$B$13/12,0) | L22: =SUM(H22:K22) | M22: =G22-L22 | N22: =N21+M22
A23: 20 | B23: 46966 | D23: 0 | E23: 0 | F23: 0 | G23: =SUM(D23:F23) | H23: 0 | I23: 166667 | J23: =Parámetros!$B$10*Parámetros!$B$12/12 | K23: =IF(N22<0,-N22*Parámetros!$B$13/12,0) | L23: =SUM(H23:K23) | M23: =G23-L23 | N23: =N22+M23
A24: 21 | B24: 46997 | D24: 0 | E24: 0 | F24: 0 | G24: =SUM(D24:F24) | H24: 0 | I24: 166667 | J24: =Parámetros!$B$10*Parámetros!$B$12/12 | K24: =IF(N23<0,-N23*Parámetros!$B$13/12,0) | L24: =SUM(H24:K24) | M24: =G24-L24 | N24: =N23+M24
A25: 22 | B25: 47027 | C25: PAC lote 2 | D25: 0 | E25: 3333333 | F25: 0 | G25: =SUM(D25:F25) | H25: 0 | I25: 0 | J25: =Parámetros!$B$10*Parámetros!$B$12/12 | K25: =IF(N24<0,-N24*Parámetros!$B$13/12,0) | L25: =SUM(H25:K25) | M25: =G25-L25 | N25: =N24+M25
A26: 23 | B26: 47058 | D26: 0 | E26: 0 | F26: 0 | G26: =SUM(D26:F26) | H26: 0 | I26: 0 | J26: =Parámetros!$B$10*Parámetros!$B$12/12 | K26: =IF(N25<0,-N25*Parámetros!$B$13/12,0) | L26: =SUM(H26:K26) | M26: =G26-L26 | N26: =N25+M26
A27: 24 | B27: 47088 | C27: Embarque lote 3 | D27: 2666667 | E27: 0 | F27: 0 | G27: =SUM(D27:F27) | H27: 3033333 | I27: 166667 | J27: =Parámetros!$B$10*Parámetros!$B$12/12 | K27: =IF(N26<0,-N26*Parámetros!$B$13/12,0) | L27: =SUM(H27:K27) | M27: =G27-L27 | N27: =N26+M27
A28: 25 | B28: 47119 | D28: 0 | E28: 0 | F28: 0 | G28: =SUM(D28:F28) | H28: 0 | I28: 166667 | J28: =Parámetros!$B$10*Parámetros!$B$12/12 | K28: =IF(N27<0,-N27*Parámetros!$B$13/12,0) | L28: =SUM(H28:K28) | M28: =G28-L28 | N28: =N27+M28
A29: 26 | B29: 47150 | C29: FAC lote 1 | D29: 0 | E29: 0 | F29: 666667 | G29: =SUM(D29:F29) | H29: 0 | I29: 166667 | J29: =Parámetros!$B$10*Parámetros!$B$12/12 | K29: =IF(N28<0,-N28*Parámetros!$B$13/12,0) | L29: =SUM(H29:K29) | M29: =G29-L29 | N29: =N28+M29
A30: 27 | B30: 47178 | D30: 0 | E30: 0 | F30: 0 | G30: =SUM(D30:F30) | H30: 0 | I30: 166667 | J30: =Parámetros!$B$10*Parámetros!$B$12/12 | K30: =IF(N29<0,-N29*Parámetros!$B$13/12,0) | L30: =SUM(H30:K30) | M30: =G30-L30 | N30: =N29+M30
A31: 28 | B31: 47209 | D31: 0 | E31: 0 | F31: 0 | G31: =SUM(D31:F31) | H31: 0 | I31: 166667 | J31: =Parámetros!$B$10*Parámetros!$B$12/12 | K31: =IF(N30<0,-N30*Parámetros!$B$13/12,0) | L31: =SUM(H31:K31) | M31: =G31-L31 | N31: =N30+M31
A32: 29 | B32: 47239 | D32: 0 | E32: 0 | F32: 0 | G32: =SUM(D32:F32) | H32: 0 | I32: 166667 | J32: =Parámetros!$B$10*Parámetros!$B$12/12 | K32: =IF(N31<0,-N31*Parámetros!$B$13/12,0) | L32: =SUM(H32:K32) | M32: =G32-L32 | N32: =N31+M32
A33: 30 | B33: 47270 | C33: PAC lote 3 | D33: 0 | E33: 3333333 | F33: 0 | G33: =SUM(D33:F33) | H33: 0 | I33: 0 | J33: =Parámetros!$B$10*Parámetros!$B$12/12 | K33: =IF(N32<0,-N32*Parámetros!$B$13/12,0) | L33: =SUM(H33:K33) | M33: =G33-L33 | N33: =N32+M33
A34: 31 | B34: 47300 | D34: 0 | E34: 0 | F34: 0 | G34: =SUM(D34:F34) | H34: 0 | I34: 0 | J34: =Parámetros!$B$10*Parámetros!$B$12/12 | K34: =IF(N33<0,-N33*Parámetros!$B$13/12,0) | L34: =SUM(H34:K34) | M34: =G34-L34 | N34: =N33+M34
A35: 32 | B35: 47331 | D35: 0 | E35: 0 | F35: 0 | G35: =SUM(D35:F35) | H35: 0 | I35: 0 | J35: =Parámetros!$B$10*Parámetros!$B$12/12 | K35: =IF(N34<0,-N34*Parámetros!$B$13/12,0) | L35: =SUM(H35:K35) | M35: =G35-L35 | N35: =N34+M35
A36: 33 | B36: 47362 | D36: 0 | E36: 0 | F36: 0 | G36: =SUM(D36:F36) | H36: 0 | I36: 0 | J36: =Parámetros!$B$10*Parámetros!$B$12/12 | K36: =IF(N35<0,-N35*Parámetros!$B$13/12,0) | L36: =SUM(H36:K36) | M36: =G36-L36 | N36: =N35+M36
A37: 34 | B37: 47392 | C37: FAC lote 2 | D37: 0 | E37: 0 | F37: 666667 | G37: =SUM(D37:F37) | H37: 0 | I37: 0 | J37: =Parámetros!$B$10*Parámetros!$B$12/12 | K37: =IF(N36<0,-N36*Parámetros!$B$13/12,0) | L37: =SUM(H37:K37) | M37: =G37-L37 | N37: =N36+M37
A38: 35 | B38: 47423 | D38: 0 | E38: 0 | F38: 0 | G38: =SUM(D38:F38) | H38: 0 | I38: 0 | J38: =Parámetros!$B$10*Parámetros!$B$12/12 | K38: =IF(N37<0,-N37*Parámetros!$B$13/12,0) | L38: =SUM(H38:K38) | M38: =G38-L38 | N38: =N37+M38
A39: 36 | B39: 47453 | D39: 0 | E39: 0 | F39: 0 | G39: =SUM(D39:F39) | H39: 0 | I39: 0 | J39: =Parámetros!$B$10*Parámetros!$B$12/12 | K39: =IF(N38<0,-N38*Parámetros!$B$13/12,0) | L39: =SUM(H39:K39) | M39: =G39-L39 | N39: =N38+M39
A40: 37 | B40: 47484 | D40: 0 | E40: 0 | F40: 0 | G40: =SUM(D40:F40) | H40: 0 | I40: 0 | J40: =Parámetros!$B$10*Parámetros!$B$12/12 | K40: =IF(N39<0,-N39*Parámetros!$B$13/12,0) | L40: =SUM(H40:K40) | M40: =G40-L40 | N40: =N39+M40
A41: 38 | B41: 47515 | D41: 0 | E41: 0 | F41: 0 | G41: =SUM(D41:F41) | H41: 0 | I41: 0 | J41: =Parámetros!$B$10*Parámetros!$B$12/12 | K41: =IF(N40<0,-N40*Parámetros!$B$13/12,0) | L41: =SUM(H41:K41) | M41: =G41-L41 | N41: =N40+M41
...

Sheet Datos proyecto
A1: DATOS CLAVE EXTRAÍDOS DE LA DOCUMENTACIÓN
A3: Cliente | B3: DHMİ – State Airports Authority (Devlet Hava Meydanları İşletmesi), Turquía
A4: Expediente / TRN | B4: 2026/760533
A5: Objeto | B5: Suministro e instalación de 21 sistemas ILS/DME + 1 sistema LLZ/DME
A6: Alcance (aeropuertos) | B6: Yozgat, Gümüşhane-Bayburt, Trabzon(2), Muğla Dalaman, Milas-Bodrum(2), Kastamonu, Kütahya Zafer(2), Sinop, Tekirdağ-Çorlu, Ağrı, Ankara Esenboğa(2), Estambul Atatürk(2), İzmir(2), Bingöl, Diyarbakır, +1 LLZ/DME Dalaman
A7: Fecha límite de oferta | B7: 28/07/2026 11:00 (aclaraciones hasta 08/07/2026)
A8: Validez de la oferta | B8: 180 días
A9: Moneda admitida | B9: TRY / USD / EUR
A10: Duración del contrato | B10: 1.935 días naturales (~5,3 años) desde la firma
A11: Plazo de entrega | B11: Máx. 3 embarques en máx. 840 días naturales
A12: Incoterm (contratista extranjero) | B12: DPU – Delivered at Place Unloaded
A13: Cobros | B13: 40% embarque · 50% formación+PAC · 10% FAC
A14: Anticipo de cliente | B14: NO (Art. 13.1)
... A28: Estado de la oferta | B28: EN PREPARACIÓN — sin lista de precios cumplimentada ni modelo económico de Turquía
A30: LISTA DE CANTIDADES (Birim Fiyat Teklif Cetveli)
A31: Concepto | B31: Cantidad
A32: Localizer (equipo + sistema de antena) | B32: 22
A33: Glide-Path (equipo + sistema de antena) | B33: 21
A34: DME (equipo + sistema de antena) | B34: 22
A35: Unidad de control/estado remoto LLZ/GP/DME | B35: 22
A36: Control remoto (PC) | B36: 65
A37: Mantenimiento remoto (portátil) | B37: 22
A38: Shelter LLZ y GP | B38: 43
A39: Set repuestos ILS (full) + carga artificial | B39: 21
A40: Set repuestos Localizer (full) + carga artificial | B40: 1
A41: Set repuestos DME | B41: 22

Sheet Lo Raro
A1: LO RARO / BANDERAS ROJAS
A3: # | B3: Severidad | C3: Hallazgo | D3: Por qué importa para el cashflow / la decisión
A4: 1 | B4: ALTA | C4: Sin anticipo + cobro muy diferido (40/50/10) durante ~5,3 años | D4: GECI debe prefinanciar el 100% de la compra a Indra antes de cobrar nada. El 40% solo llega contra embarque; el 50% tras instalar+formar+PAC (meses después) y el 10% un año después de la PAC. El pico de caja negativa es enorme.
A5: 2 | B5: ALTA | C5: Precio FIJO sin revisión (Art. 14/43) en un contrato de 5,3 años | D5: Cualquier subida de coste de Indra/IACIT, logística, aduanas o FX a lo largo de 5 años NO es recuperable. Si además se oferta en TRY, el riesgo divisa/inflación turca es crítico.
A6: 3 | B6: ALTA | C6: No existe oferta económica de Turquía | D6: La carpeta 01_Economical_Proposals solo tiene plantillas de OTROS países (Angola, Fiji, Perú, Geci Española...). Para una oferta que vence el 28/07/2026 no hay coste ni precio montado: el cashflow se basa en estimaciones.
A7: 4 | B7: MEDIA | C7: Cifras de valor incoherentes entre sí | D7: El requisito de experiencia (20% ≈ 5 M€) implica ~25 M€ de oferta, pero los avales (3%≈600k€ y 6%≈1,2M€) implican ~20 M€. Hay que fijar el valor estimado real del contrato.
A8: 5 | B8: MEDIA | C8: Avales inmovilizados grandes y largos | D8: Bid bond ~600k€ + performance bond ~1,2M€ (6%). El de cumplimiento solo se libera al 50% tras PAC y el resto tras 2 años de garantía: línea de avales ocupada años.
A9: 6 | B9: MEDIA | C9: Dependencia de proveedor único (Indra) con certificaciones críticas | D9: Sin Authorised Dealer Certificate + Manufacturer's Certificate + evidencia CAT III + Flight Check Report de Indra, NO se puede ni licitar. Single point of failure y posible apalancamiento de Indra en precio/plazos.
A10: 7 | B10: MEDIA | C10: Prohibida la subcontratación (Art. 15) | D10: El modelo GECI (comprar a Indra/IACIT e instalar) debe estructurarse como compra de suministro o como UTE; los consorcios NO se admiten. Riesgo legal/estructura a cerrar antes de ofertar.
A11: 8 | B11: MEDIA | C11: Aduanas/importación y DPU a cargo del contratista | D11: Transporte, despacho, almacenaje y permisos de importación los gestiona/adelanta GECI (impuestos los paga DHMİ pero el proceso lo financia el contratista). Más capital circulante y complejidad.
A12: 9 | B12: BAJA | C12: Factibilidad interna 53% — 'APTO' pero borderline | D12: La propia hoja F-POI-16/15 puntúa 53% y marca financiación (aval y adquisiciones) como riesgo. Coherente con el problema de caja.
A13: 10 | B13: BAJA | C13: Cantidades a verificar (PC=65, shelters=43, repuestos Localizer=1) | D13: Reconcilian con 21 ILS+1 LLZ, pero conviene validar 65 PCs de control remoto y la asimetría de sets de repuestos antes de cifrar.
A14: 11 | B14: BAJA | C14: PAC/FAC 'pueden' ser por aeropuerto | D14: Si se negocia aceptación separada por aeropuerto, se adelantan cobros y mejora la caja; pero es discrecional del cliente ('may'), no garantizado.
